Workbook
Name DeptList: [1]List!$I$4:$I$24
Name Impact_list: list!$B$4:$B$8
Name Issue: list!$B$19:$B$21
Name PhaseList: [1]List!$C$3:$C$7
Name Priority_list: [1]List!$C$59:$C$63
Name Prob_list: list!$A$11:$A$15
Name Report_Period_Week: list!$H$3:$H$54

Sheet Macros
AV136: Schedule
AW137: 3 | AX137: 5 | AY137: On Track
AW138: 2 | AX138: 2 | AY138: Managed Delay
AW139: 1 | AX139: 4 | AY139: Off Track
AV141: Scope
AW142: 3 | AX142: 7 | AY142: Controlled
AW143: 2 | AX143: 3 | AY143: Accepted Variance
AW144: 1 | AX144: 1 | AY144: Uncontrolled
AV146: Quality
AW147: 3 | AX147: 6 | AY147: High
AW148: 2 | AX148: 8 | AY148: Meduim
AW149: 1 | AX149: 9 | AY149: Low
AV152: Risks
AW153: 1 | AX153: 8 | AY153: Low Risk
AW154: 7 | AX154: 6 | AY154: Moderate Risk
AW155: 14 | AX155: 10 | AY155: High Risk

Sheet Dashboard
F6: PMO - Project Progress Report (PPR)
F9: Project Name > | G9: =IF('Fill out report تعبئة التقرير'!#REF!="","",'Fill out report تعبئة التقرير'!#REF!) -> #REF! | P9: Planned Project Length > | Q9: =IF('Fill out report تعبئة التقرير'!#REF!="N/A","",'Fill out report تعبئة التقرير'!#REF! & " Days") -> #REF!
G11: Report Period From> | I11: =IF('Fill out report تعبئة التقرير'!#REF!="","",'Fill out report تعبئة التقرير'!#REF! & " "& 'Fill out report تعبئة التقرير'!#REF!) -> #REF! | K11: Report Period To > | M11: =IF('Fill out report تعبئة التقرير'!#REF!="","",'Fill out report تعبئة التقرير'!#REF! & " "& 'Fill out report تعبئة التقرير'!#REF!) -> #REF! | P11: Actual Project Length > | Q11: =IF('Fill out report تعبئة التقرير'!#REF!="N/A","",'Fill out report تعبئة التقرير'!#REF! & " Days") -> #REF!
F13: Project Phase | P13: Project Planned End Date > | Q13: =IF('Fill out report تعبئة التقرير'!#REF!="","",'Fill out report تعبئة التقرير'!#REF!) -> #REF!
K14: Executing & Controlling
G15: Initiation | I15: Planning | N15: Closing | P15: % of Delay in project > | Q15: =IF('Fill out report تعبئة التقرير'!#REF!="N/A","",'Fill out report تعبئة التقرير'!#REF!) -> #REF!
F17: Project Start | N17: Project End | P17: Overall Status -RAG(Previous / New) > | Q17: ='Fill out report تعبئة التقرير'!#REF! -> #REF! | R17: ='Fill out report تعبئة التقرير'!#REF! -> #REF!
F19: Project Dashboard
F21: % of Completion > | N21: Project Risks >
F32: Project Milestones > | N32: Project Issues >
E44: 1 | F44: Project Progress Report Template v 1.1

Sheet Fill out report  تعبئة التقرير
E7: تقرير أداء المشروع Project Progress Report (PPR)
E9: معلومات المشروع Project Information
E11: اسم المشروع Project Name | M11: تاريخ بداية المشروع Project Start Date
E12: رمز المشروع Project Code | M12: تاريخ نهاية المشروع Project End Date
E13: القطاع Sector | M13: راعي المشروع Project Sponsor
E14: اسم المورد ( إن وجد) Vendor Name (if any) | M14: مالك المشروع Project Owner
M15: مدير المشروع Project Manager
E16: الميزانية المحجوزة Allocated Budget | F16: =SUM(O28:P76) -> 0 | M16: فترة التقرير من تاريخ Report Period From
E17: المبلغ الفعلي المصروف Actual Spent Amount | F17: =SUMIF(Q28:Q76, "Yes",O28:O76) -> 0 | M17: إلى تاريخ To Date
E19: حالة المشروع Project Health | F19: =IFERROR(((($F$21*0.51)+($F$22*0.29)+($F$23*0.2))),"") -> 3 | G19: =(IF(F19>=2.7,"وفق المخطط له [On Track]",IF(F19>=2,"تقريبا وفق المخطط له [Generally On Track]",IF(F19 <2,"خارج المخطط له [ Off Track]","--")))) -> وفق المخطط له [On Track] | O19: 3 | P19: <-----الفترة السابقة (يدوي) Previous Period ( Manual )
E20: وصف حالة المشروع ( الجدول الزمني ، الميزانية ، نطاق العمل ، المورد / الموارد )
E21: حالة الجدول الزمني Schedule Status | F21: =IF( (Q96-Q94) <= 5%,3,IF((Q96-Q94)>15%,1,2) ) -> 3 | G21: =IF(F21="","",LOOKUP(F21, {1,2,3}, {" متأخر [Unmanaged Delayed] ","احتمال وجود تأخير [ Managed Delayed]"," وفق الخطة [On-Time]"})) -> وفق الخطة [On-Time]
E22: حالة نطاق العمل Scope Status | F22: 3 | G22: =IF(F22="","",LOOKUP(F22, {1,2,3}, {"خارج النطاق [Uncontrolled]","تغيرات مقبولة [Accepted Variance]","ضمن النطاق [Controlled]"})) -> ضمن النطاق [Controlled]
E23: حالة الموارد / الشركة المنفذة Resource/Vendor Status | F23: 3 | G23: =IF(F23="","",LOOKUP(F23, {1,2,3}, {"معوقات عالية [High Issue]","معوقات متوسطة [Midum Issue]","لا يوجد معوقات [No Issue]"})) -> لا يوجد معوقات [No Issue]
E25: المشروع (المعالم / الأنشطة / المستلمات) Project (Milestones / Task / Deliverables)
E27: المعالم/التسليمات Milstones/Major Tasks | I27: تاريخ البدء Start Date | J27: تاريخ النهاية End date | K27: الإنجاز % % Complete | L27: التسليمات المرتبط بدفعات Paid Deliverables | O27: قيمة الدفعة Payment Amount | Q27: تم الدفع (نعم/لا) Paid (Yes/No) | R27: الحالة Status
R28: =IF(J28="","",IF(AND(J28<=TODAY(),K28<100%),1,IF(AND(K28=100%,L28>"",Q28<>"Yes"),2,IF(OR(AND(J28>=Q28,Q28<>"",J28>TODAY()),J28>TODAY()),3,IF(AND(J28<>"",Q28<>"",K28=100%),3,3)))))
R29: =IF(J29="","",IF(AND(J29<=TODAY(),K29<100%),1,IF(AND(K29=100%,L29>"",Q29<>"Yes"),2,IF(OR(AND(J29>=Q29,Q29<>"",J29>TODAY()),J29>TODAY()),3,IF(AND(J29<>"",Q29<>"",K29=100%),3,3)))))
R30: =IF(J30="","",IF(AND(J30<=TODAY(),K30<100%),1,IF(AND(K30=100%,L30>"",Q30<>"Yes"),2,IF(OR(AND(J30>=Q30,Q30<>"",J30>TODAY()),J30>TODAY()),3,IF(AND(J30<>"",Q30<>"",K30=100%),3,3)))))
R31: =IF(J31="","",IF(AND(J31<=TODAY(),K31<100%),1,IF(AND(K31=100%,L31>"",Q31<>"Yes"),2,IF(OR(AND(J31>=Q31,Q31<>"",J31>TODAY()),J31>TODAY()),3,IF(AND(J31<>"",Q31<>"",K31=100%),3,3)))))
R32: =IF(J32="","",IF(AND(J32<=TODAY(),K32<100%),1,IF(AND(K32=100%,L32>"",Q32<>"Yes"),2,IF(OR(AND(J32>=Q32,Q32<>"",J32>TODAY()),J32>TODAY()),3,IF(AND(J32<>"",Q32<>"",K32=100%),3,3)))))
R33: =IF(J33="","",IF(AND(J33<=TODAY(),K33<100%),1,IF(AND(K33=100%,L33>"",Q33<>"Yes"),2,IF(OR(AND(J33>=Q33,Q33<>"",J33>TODAY()),J33>TODAY()),3,IF(AND(J33<>"",Q33<>"",K33=100%),3,3)))))
R34: =IF(J34="","",IF(AND(J34<=TODAY(),K34<100%),1,IF(AND(K34=100%,L34>"",Q34<>"Yes"),2,IF(OR(AND(J34>=Q34,Q34<>"",J34>TODAY()),J34>TODAY()),3,IF(AND(J34<>"",Q34<>"",K34=100%),3,3)))))
R35: =IF(J35="","",IF(AND(J35<=TODAY(),K35<100%),1,IF(AND(K35=100%,L35>"",Q35<>"Yes"),2,IF(OR(AND(J35>=Q35,Q35<>"",J35>TODAY()),J35>TODAY()),3,IF(AND(J35<>"",Q35<>"",K35=100%),3,3)))))
R36: =IF(J36="","",IF(AND(J36<=TODAY(),K36<100%),1,IF(AND(K36=100%,L36>"",Q36<>"Yes"),2,IF(OR(AND(J36>=Q36,Q36<>"",J36>TODAY()),J36>TODAY()),3,IF(AND(J36<>"",Q36<>"",K36=100%),3,3)))))
R37: =IF(J37="","",IF(AND(J37<=TODAY(),K37<100%),1,IF(AND(K37=100%,L37>"",Q37<>"Yes"),2,IF(OR(AND(J37>=Q37,Q37<>"",J37>TODAY()),J37>TODAY()),3,IF(AND(J37<>"",Q37<>"",K37=100%),3,3)))))
R38: =IF(J38="","",IF(AND(J38<=TODAY(),K38<100%),1,IF(AND(K38=100%,L38>"",Q38<>"Yes"),2,IF(OR(AND(J38>=Q38,Q38<>"",J38>TODAY()),J38>TODAY()),3,IF(AND(J38<>"",Q38<>"",K38=100%),3,3)))))
R39: =IF(J39="","",IF(AND(J39<=TODAY(),K39<100%),1,IF(AND(K39=100%,L39>"",Q39<>"Yes"),2,IF(OR(AND(J39>=Q39,Q39<>"",J39>TODAY()),J39>TODAY()),3,IF(AND(J39<>"",Q39<>"",K39=100%),3,3)))))
... R76: =IF(J76="","",IF(AND(J76<=TODAY(),K76<100%),1,IF(AND(K76=100%,L76>"",Q76<>"Yes"),2,IF(OR(AND(J76>=Q76,Q76<>"",J76>TODAY()),J76>TODAY()),3,IF(AND(J76<>"",Q76<>"",K76=100%),3,3)))))
E78: إنجازات المشروع Project Achievements
E80: المنجز في هذه الفترة Achieved in this Period For new line press : "Alt + Enter | K80: المخطط إنجازه في الفترة القادمة Planned for the Next Period For new line press : "Alt + Enter
BR86: FOR CHARTS AND CALCULATIONS | BV86: DON'T CHANGE ANY VALUE | CA86: DON'T CHANGE ANY VALUE
BW87: Milestones | BX87: Milestones | BY87: Milestones | BZ87: Milestones
BR88: Planned Project Period (1st Baseline) | BS88: Actual Project Period | BT88: Variance based on baseline | BU88: % of Delay (1st Baseline) | BV88: No. of Milestones | BW88: Achieved | BX88: In Progress | BY88: Overdue | BZ88: Not Started Yet | CA88: No. of Risks | CB88: High Risks | CC88: Moderate Risks | CD88: Low Risks | CE88: No. of Issues | CF88: High Issues | CG88: Medium Issues | CH88: Low Issues | CI88: Variance % of Completion
BR89: =IF(OR(#REF!="",#REF!=""),"N/A",#REF!-#REF!) -> #REF! | BS89: =IFERROR(IF(#REF!="","N/A",IF(#REF!="",TODAY()-#REF!,#REF!-#REF!)),"?") -> ? | BT89: =IFERROR(IF(#REF!="","N/A",IF(#REF!="","",BS89-BR89)),"?") -> ? | BU89: =IFERROR(IF(#REF!="","N/A",(IF(BT89="N/A","N/A",IF((BT89/BR89)<0,0,BT89/BR89)))),"?") -> ? | BV89: =COUNT(#REF!) -> 0 | BW89: =COUNTIFS(#REF!,"<>",#REF!,"<>",#REF!,"=100%") -> #REF! | BX89: =COUNTIFS(#REF!,"<>",#REF!,"<100%",#REF!,">0%",#REF!,">="&TODAY()) -> #REF! | BY89: =COUNTIFS(#REF!,"<>",#REF!,"<100%",#REF!,"<"&TODAY()) -> #REF! | BZ89: =COUNTIFS(#REF!,"<>",#REF!,"=0%",#REF!,">"&TODAY()) -> #REF! | CA89: =COUNTIFS('Fill out report تعبئة التقرير'!#REF!,"<>",'Fill out report تعبئة التقرير'!#REF!,"<>0") -> #REF! | CB89: =COUNTIFS('Fill out report تعبئة التقرير'!#REF!,"<>",'Fill out report تعبئة التقرير'!#REF!,">=13") -> #REF! | CC89: =COUNTIFS('Fill out report تعبئة التقرير'!#REF!,"<>",'Fill out report تعبئة التقرير'!#REF!,">4")-COUNTIFS('Fill out report تعبئة التقرير'!#REF!,"<>",'Fill out report تعبئة التقرير'!#REF!,">=13") -> #REF! | CD89: =COUNTIFS('Fill out report تعبئة التقرير'!#REF!,"<>",'Fill out report تعبئة التقرير'!#REF!,">0")-COUNTIFS('Fill out report تعبئة التقرير'!#REF!,"<>",'Fill out report تعبئة التقرير'!#REF!,">4") -> #REF! | CE89: =COUNTIFS('Fill out report تعبئة التقرير'!$G13:$G27,"<>",'Fill out report تعبئة التقرير'!$F13:$F27,"<>0") -> 4 | CF89: =COUNTIFS('Fill out report تعبئة التقرير'!$G13:$G27,"<>",'Fill out report تعبئة التقرير'!$F13:$F27,"=3") -> 4 | CG89: =COUNTIFS('Fill out report تعبئة التقرير'!$G13:$G27,"<>",'Fill out report تعبئة التقرير'!$F13:$F27,"=2") -> 0 | CH89: =COUNTIFS('Fill out report تعبئة التقرير'!$G13:$G27,"<>",'Fill out report تعبئة التقرير'!$F13:$F27,"=1") -> 0 | CI89: =#REF!-#REF! -> #REF!
E92: ملاحظات مدير المشروع Project Manager Comment
E94: ملاحظات مدير المشروع PM Comment For new line press : "Alt + Enter | O94: الإنجاز الحالي % % of Completion (Current)
O96: المخطط إنجازه % % Planned
E98: =" [300 char max] [ " & LEN(G94)& " char typed ]" -> [300 char max] [ 0 char typed ] | O98: الإنجاز السابق % % Completion (Previous)
E101: مخاطر المشروع Project Risks | F101: =MAX(AN104:AN113) -> 0 | G101: =LOOKUP(F101, {0,1,7,10}, {"لا يوجد مخاطر [No Risks]","يوجد مخاطر منخفضة [Low Risks]","يوجد مخاطر متوسطة [Medium Risks]","يوجد مخاطر عالية [High Risks]"}) -> لا يوجد مخاطر [No Risks] | AN101: DON'T CHANGE ANY VALUE
...

Sheet Extract 
A1: Project Name | B1: Sector | C1: Vendor Name | D1: Project Code | E1: Project Sponsor | F1: Project Owner | G1: Project Manager | H1: Phase | I1: Project Start Date | J1: Project End Date | K1: Estimated End Date | L1: Allocated Budget | M1: Actual Spend | N1: Planned to Spend | O1: RAG - Previous | P1: RAG - Current | Q1: RAG - Schedule | R1: RAG - Scope | S1: RAG - Resources | T1: Previous - %Completion | U1: Current - %Completion | V1: Planned - %Completion | W1: Planned Project Period | X1: Actual Project Period | Y1: Schedule Variance | Z1: %Delayed | AA1: Max Milestone Date | AB1: Achivements | AC1: Next Tasks | AD1: Issues | AE1: Risks | AF1: PM Comments | AG1: Help Required | AH1: Milestones | AI1: Milestone Start Date | AJ1: Milestone End Date | AK1: Milestone % Completion | AL1: Deliverables | AM1: Payment Amount | AN1: Paid | AO1: Flag | AP1: Reporting Period From | AQ1: Reporting Period To
A2: ='Fill out report تعبئة التقرير'!F11 -> 0 | B2: ='Fill out report تعبئة التقرير'!F13 -> 0 | C2: ='Fill out report تعبئة التقرير'!F14 -> 0 | D2: ='Fill out report تعبئة التقرير'!F12 -> 0 | E2: ='Fill out report تعبئة التقرير'!P13 -> 0 | F2: ='Fill out report تعبئة التقرير'!P14 -> 0 | G2: ='Fill out report تعبئة التقرير'!P15 -> 0 | H2: ='Fill out report تعبئة التقرير'!F15 -> 0 | I2: ='Fill out report تعبئة التقرير'!P11 -> 0 | J2: ='Fill out report تعبئة التقرير'!P12 -> 0 | K2: ='Fill out report تعبئة التقرير'!P12 -> 0 | L2: ='Fill out report تعبئة التقرير'!F16 -> 0 | M2: ='Fill out report تعبئة التقرير'!F17 -> 0 | N2: =SUMIF(AJ2:AJ19, "<=" &TODAY(), AM2:AM19) -> 0 | O2: ='Fill out report تعبئة التقرير'!O19 -> 3 | P2: =IF('Fill out report تعبئة التقرير'!G19= "وفق المخطط له [On Track]",3, IF('Fill out report تعبئة التقرير'!G19 = "تقريبا وفق المخطط له [Generally On Track]",2, IF('Fill out report تعبئة التقرير'!G19="خارج المخطط له [ Off Track]", 1, ""))) -> 3 | Q2: ='Fill out report تعبئة التقرير'!F21 -> 3 | R2: ='Fill out report تعبئة التقرير'!F22 -> 3 | S2: ='Fill out report تعبئة التقرير'!F23 -> 3 | T2: ='Fill out report تعبئة التقرير'!Q98 -> 0 | U2: ='Fill out report تعبئة التقرير'!Q94 -> 0 | V2: ='Fill out report تعبئة التقرير'!Q96 -> 0 | W2: =J2-I2 -> 0 | X2: =IF(AA2>J2,AA2-I2,J2-I2) -> 0 | Y2: =X2-W2 -> 0 | Z2: =V2-U2 -> 0 | AA2: =MAX(AJ2:AJ51) -> 0 | AB2: =IF('Fill out report تعبئة التقرير'!F80="","",'Fill out report تعبئة التقرير'!F80) | AC2: =IF('Fill out report تعبئة التقرير'!M80="","",'Fill out report تعبئة التقرير'!M80) | AD2: =IF('Fill out report تعبئة التقرير'!F120=3,"- "&'Fill out report تعبئة التقرير'!G120&CHAR(10)," ")&IF('Fill out report تعبئة التقرير'!F121=3,"- "&'Fill out report تعبئة التقرير'!G121&CHAR(10)," ")&IF('Fill out report تعبئة التقرير'!F122=3,"- "&'Fill out report تعبئة التقرير'!G122&CHAR(10)," ")&IF('Fill out report تعبئة التقرير'!F123=3,"- "&'Fill out report تعبئة التقرير'!G123&CHAR(10)," ")&IF('Fill out report تعبئة التقرير'!F124=3,"- "&'Fill out report تعبئة التقرير'!G124&CHAR(10)," ")&IF('Fill out report تعبئة التقرير'!F125=3,"- "&'Fill out report تعبئة التقرير'!G125&CHAR(10)," ")&IF('Fill out report تعبئة التقرير'!F126=3,"- "&'Fill out report تعبئة التقرير'!G126&CHAR(10)," ")&IF('Fill out report تعبئة التقرير'!F127=3,"- "&'Fill out report تعبئة التقرير'!G127&CHAR(10)," ")&IF('Fill out report تعبئة التقرير'!F128=3,"- "&'Fill out report تعبئة التقرير'!G128&CHAR(10)," ")&IF('Fill out report تعبئة التقرير'!F129=3,"- "&'Fill out report تعبئة التقرير'!G129," ") | AE2: =IF('Fill out report تعبئة التقرير'!F104>9,"- "&'Fill out report تعبئة التقرير'!G104&CHAR(10)," ")&IF('Fill out report تعبئة التقرير'!F105>9,"- "&'Fill out report تعبئة التقرير'!G105&CHAR(10)," ")&IF('Fill out report تعبئة التقرير'!F106>9,"- "&'Fill out report تعبئة التقرير'!G106&CHAR(10)," ")&IF('Fill out report تعبئة التقرير'!F107>9,"- "&'Fill out report تعبئة التقرير'!G107&CHAR(10)," ")&IF('Fill out report تعبئة التقرير'!F108>9,"- "&'Fill out report تعبئة التقرير'!G108&CHAR(10)," ")&IF('Fill out report تعبئة التقرير'!F109>9,"- "&'Fill out report تعبئة التقرير'!G109&CHAR(10)," ")&IF('Fill out report تعبئة التقرير'!F110>9,"- "&'Fill out report تعبئة التقرير'!G110&CHAR(10)," ")&IF('Fill out report تعبئة التقرير'!F111>9,"- "&'Fill out report تعبئة التقرير'!G111&CHAR(10)," ")&IF('Fill out report تعبئة التقرير'!F112>9,"- "&'Fill out report تعبئة التقرير'!G112&CHAR(10)," ")&IF('Fill out report تعبئة التقرير'!F113>9,"- "&'Fill out report تعبئة التقرير'!G113," ") | AF2: =IF('Fill out report تعبئة التقرير'!G94="","",'Fill out report تعبئة التقرير'!G94) | AG2: =IF('Fill out report تعبئة التقرير'!G134<>"","- "&'Fill out report تعبئة التقرير'!G134," ")& IF('Fill out report تعبئة التقرير'!G135<>"",CHAR(10)&"- "&'Fill out report تعبئة التقرير'!G135," ")& IF('Fill out report تعبئة التقرير'!G136<>"",CHAR(10)&"- "&'Fill out report تعبئة التقرير'!G136," ") | AH2: =IF('Fill out report تعبئة التقرير'!E28 >=" ",'Fill out report تعبئة التقرير'!E28,"") | AI2: =IF('Fill out report تعبئة التقرير'!I28 > 0,'Fill out report تعبئة التقرير'!I28,"") | AJ2: =IF('Fill out report تعبئة التقرير'!J28 > 0,'Fill out report تعبئة التقرير'!J28,"") | AK2: =IF('Fill out report تعبئة التقرير'!K28 >=0,'Fill out report تعبئة التقرير'!K28,"") -> 0 | AL2: =IF('Fill out report تعبئة التقرير'!L28 >=" ",'Fill out report تعبئة التقرير'!L28,"") | AM2: =IF('Fill out report تعبئة التقرير'!O28 > 0,'Fill out report تعبئة التقرير'!O28,"") | AN2: =IF('Fill out report تعبئة التقرير'!Q28 >=" ",'Fill out report تعبئة التقرير'!Q28,"") | AO2: =IF('Fill out report تعبئة التقرير'!R28 > 0,'Fill out report تعبئة التقرير'!R28,"") | AP2: ='Fill out report تعبئة التقرير'!P16 -> 0 | AQ2: ='Fill out report تعبئة التقرير'!P17 -> 0
AH3: =IF('Fill out report تعبئة التقرير'!E29 >=" ",'Fill out report تعبئة التقرير'!E29,"") | AI3: =IF('Fill out report تعبئة التقرير'!I29 > 0,'Fill out report تعبئة التقرير'!I29,"") | AJ3: =IF('Fill out report تعبئة التقرير'!J29 > 0,'Fill out report تعبئة التقرير'!J29,"") | AK3: =IF('Fill out report تعبئة التقرير'!K29 >=0,'Fill out report تعبئة التقرير'!K29,"") -> 0 | AL3: =IF('Fill out report تعبئة التقرير'!L29 >=" ",'Fill out report تعبئة التقرير'!L29,"") | AM3: =IF('Fill out report تعبئة التقرير'!O29 > 0,'Fill out report تعبئة التقرير'!O29,"") | AN3: =IF('Fill out report تعبئة التقرير'!Q29 >=" ",'Fill out report تعبئة التقرير'!Q29,"") | AO3: =IF('Fill out report تعبئة التقرير'!R29 > 0,'Fill out report تعبئة التقرير'!R29,"")
AH4: =IF('Fill out report تعبئة التقرير'!E30 >=" ",'Fill out report تعبئة التقرير'!E30,"") | AI4: =IF('Fill out report تعبئة التقرير'!I30 > 0,'Fill out report تعبئة التقرير'!I30,"") | AJ4: =IF('Fill out report تعبئة التقرير'!J30 > 0,'Fill out report تعبئة التقرير'!J30,"") | AK4: =IF('Fill out report تعبئة التقرير'!K30 >=0,'Fill out report تعبئة التقرير'!K30,"") -> 0 | AL4: =IF('Fill out report تعبئة التقرير'!L30 >=" ",'Fill out report تعبئة التقرير'!L30,"") | AM4: =IF('Fill out report تعبئة التقرير'!O30 > 0,'Fill out report تعبئة التقرير'!O30,"") | AN4: =IF('Fill out report تعبئة التقرير'!Q30 >=" ",'Fill out report تعبئة التقرير'!Q30,"") | AO4: =IF('Fill out report تعبئة التقرير'!R30 > 0,'Fill out report تعبئة التقرير'!R30,"")
AH5: =IF('Fill out report تعبئة التقرير'!E31 >=" ",'Fill out report تعبئة التقرير'!E31,"") | AI5: =IF('Fill out report تعبئة التقرير'!I31 > 0,'Fill out report تعبئة التقرير'!I31,"") | AJ5: =IF('Fill out report تعبئة التقرير'!J31 > 0,'Fill out report تعبئة التقرير'!J31,"") | AK5: =IF('Fill out report تعبئة التقرير'!K31 >=0,'Fill out report تعبئة التقرير'!K31,"") -> 0 | AL5: =IF('Fill out report تعبئة التقرير'!L31 >=" ",'Fill out report تعبئة التقرير'!L31,"") | AM5: =IF('Fill out report تعبئة التقرير'!O31 > 0,'Fill out report تعبئة التقرير'!O31,"") | AN5: =IF('Fill out report تعبئة التقرير'!Q31 >=" ",'Fill out report تعبئة التقرير'!Q31,"") | AO5: =IF('Fill out report تعبئة التقرير'!R31 > 0,'Fill out report تعبئة التقرير'!R31,"")
AH6: =IF('Fill out report تعبئة التقرير'!E32 >=" ",'Fill out report تعبئة التقرير'!E32,"") | AI6: =IF('Fill out report تعبئة التقرير'!I32 > 0,'Fill out report تعبئة التقرير'!I32,"") | AJ6: =IF('Fill out report تعبئة التقرير'!J32 > 0,'Fill out report تعبئة التقرير'!J32,"") | AK6: =IF('Fill out report تعبئة التقرير'!K32 >=0,'Fill out report تعبئة التقرير'!K32,"") -> 0 | AL6: =IF('Fill out report تعبئة التقرير'!L32 >=" ",'Fill out report تعبئة التقرير'!L32,"") | AM6: =IF('Fill out report تعبئة التقرير'!O32 > 0,'Fill out report تعبئة التقرير'!O32,"") | AN6: =IF('Fill out report تعبئة التقرير'!Q32 >=" ",'Fill out report تعبئة التقرير'!Q32,"") | AO6: =IF('Fill out report تعبئة التقرير'!R32 > 0,'Fill out report تعبئة التقرير'!R32,"")
AH7: =IF('Fill out report تعبئة التقرير'!E33 >=" ",'Fill out report تعبئة التقرير'!E33,"") | AI7: =IF('Fill out report تعبئة التقرير'!I33 > 0,'Fill out report تعبئة التقرير'!I33,"") | AJ7: =IF('Fill out report تعبئة التقرير'!J33 > 0,'Fill out report تعبئة التقرير'!J33,"") | AK7: =IF('Fill out report تعبئة التقرير'!K33 >=0,'Fill out report تعبئة التقرير'!K33,"") -> 0 | AL7: =IF('Fill out report تعبئة التقرير'!L33 >=" ",'Fill out report تعبئة التقرير'!L33,"") | AM7: =IF('Fill out report تعبئة التقرير'!O33 > 0,'Fill out report تعبئة التقرير'!O33,"") | AN7: =IF('Fill out report تعبئة التقرير'!Q33 >=" ",'Fill out report تعبئة التقرير'!Q33,"") | AO7: =IF('Fill out report تعبئة التقرير'!R33 > 0,'Fill out report تعبئة التقرير'!R33,"")
AH8: =IF('Fill out report تعبئة التقرير'!E34 >=" ",'Fill out report تعبئة التقرير'!E34,"") | AI8: =IF('Fill out report تعبئة التقرير'!I34 > 0,'Fill out report تعبئة التقرير'!I34,"") | AJ8: =IF('Fill out report تعبئة التقرير'!J34 > 0,'Fill out report تعبئة التقرير'!J34,"") | AK8: =IF('Fill out report تعبئة التقرير'!K34 >=0,'Fill out report تعبئة التقرير'!K34,"") -> 0 | AL8: =IF('Fill out report تعبئة التقرير'!L34 >=" ",'Fill out report تعبئة التقرير'!L34,"") | AM8: =IF('Fill out report تعبئة التقرير'!O34 > 0,'Fill out report تعبئة التقرير'!O34,"") | AN8: =IF('Fill out report تعبئة التقرير'!Q34 >=" ",'Fill out report تعبئة التقرير'!Q34,"") | AO8: =IF('Fill out report تعبئة التقرير'!R34 > 0,'Fill out report تعبئة التقرير'!R34,"")
AH9: =IF('Fill out report تعبئة التقرير'!E35 >=" ",'Fill out report تعبئة التقرير'!E35,"") | AI9: =IF('Fill out report تعبئة التقرير'!I35 > 0,'Fill out report تعبئة التقرير'!I35,"") | AJ9: =IF('Fill out report تعبئة التقرير'!J35 > 0,'Fill out report تعبئة التقرير'!J35,"") | AK9: =IF('Fill out report تعبئة التقرير'!K35 >=0,'Fill out report تعبئة التقرير'!K35,"") -> 0 | AL9: =IF('Fill out report تعبئة التقرير'!L35 >=" ",'Fill out report تعبئة التقرير'!L35,"") | AM9: =IF('Fill out report تعبئة التقرير'!O35 > 0,'Fill out report تعبئة التقرير'!O35,"") | AN9: =IF('Fill out report تعبئة التقرير'!Q35 >=" ",'Fill out report تعبئة التقرير'!Q35,"") | AO9: =IF('Fill out report تعبئة التقرير'!R35 > 0,'Fill out report تعبئة التقرير'!R35,"")
AH10: =IF('Fill out report تعبئة التقرير'!E36 >=" ",'Fill out report تعبئة التقرير'!E36,"") | AI10: =IF('Fill out report تعبئة التقرير'!I36 > 0,'Fill out report تعبئة التقرير'!I36,"") | AJ10: =IF('Fill out report تعبئة التقرير'!J36 > 0,'Fill out report تعبئة التقرير'!J36,"") | AK10: =IF('Fill out report تعبئة التقرير'!K36 >=0,'Fill out report تعبئة التقرير'!K36,"") -> 0 | AL10: =IF('Fill out report تعبئة التقرير'!L36 >=" ",'Fill out report تعبئة التقرير'!L36,"") | AM10: =IF('Fill out report تعبئة التقرير'!O36 > 0,'Fill out report تعبئة التقرير'!O36,"") | AN10: =IF('Fill out report تعبئة التقرير'!Q36 >=" ",'Fill out report تعبئة التقرير'!Q36,"") | AO10: =IF('Fill out report تعبئة التقرير'!R36 > 0,'Fill out report تعبئة التقرير'!R36,"")
AH11: =IF('Fill out report تعبئة التقرير'!E37 >=" ",'Fill out report تعبئة التقرير'!E37,"") | AI11: =IF('Fill out report تعبئة التقرير'!I37 > 0,'Fill out report تعبئة التقرير'!I37,"") | AJ11: =IF('Fill out report تعبئة التقرير'!J37 > 0,'Fill out report تعبئة التقرير'!J37,"") | AK11: =IF('Fill out report تعبئة التقرير'!K37 >=0,'Fill out report تعبئة التقرير'!K37,"") -> 0 | AL11: =IF('Fill out report تعبئة التقرير'!L37 >=" ",'Fill out report تعبئة التقرير'!L37,"") | AM11: =IF('Fill out report تعبئة التقرير'!O37 > 0,'Fill out report تعبئة التقرير'!O37,"") | AN11: =IF('Fill out report تعبئة التقرير'!Q37 >=" ",'Fill out report تعبئة التقرير'!Q37,"") | AO11: =IF('Fill out report تعبئة التقرير'!R37 > 0,'Fill out report تعبئة التقرير'!R37,"")
AH12: =IF('Fill out report تعبئة التقرير'!E38 >=" ",'Fill out report تعبئة التقرير'!E38,"") | AI12: =IF('Fill out report تعبئة التقرير'!I38 > 0,'Fill out report تعبئة التقرير'!I38,"") | AJ12: =IF('Fill out report تعبئة التقرير'!J38 > 0,'Fill out report تعبئة التقرير'!J38,"") | AK12: =IF('Fill out report تعبئة التقرير'!K38 >=0,'Fill out report تعبئة التقرير'!K38,"") -> 0 | AL12: =IF('Fill out report تعبئة التقرير'!L38 >=" ",'Fill out report تعبئة التقرير'!L38,"") | AM12: =IF('Fill out report تعبئة التقرير'!O38 > 0,'Fill out report تعبئة التقرير'!O38,"") | AN12: =IF('Fill out report تعبئة التقرير'!Q38 >=" ",'Fill out report تعبئة التقرير'!Q38,"") | AO12: =IF('Fill out report تعبئة التقرير'!R38 > 0,'Fill out report تعبئة التقرير'!R38,"")
AH13: =IF('Fill out report تعبئة التقرير'!E39 >=" ",'Fill out report تعبئة التقرير'!E39,"") | AI13: =IF('Fill out report تعبئة التقرير'!I39 > 0,'Fill out report تعبئة التقرير'!I39,"") | AJ13: =IF('Fill out report تعبئة التقرير'!J39 > 0,'Fill out report تعبئة التقرير'!J39,"") | AK13: =IF('Fill out report تعبئة التقرير'!K39 >=0,'Fill out report تعبئة التقرير'!K39,"") -> 0 | AL13: =IF('Fill out report تعبئة التقرير'!L39 >=" ",'Fill out report تعبئة التقرير'!L39,"") | AM13: =IF('Fill out report تعبئة التقرير'!O39 > 0,'Fill out report تعبئة التقرير'!O39,"") | AN13: =IF('Fill out report تعبئة التقرير'!Q39 >=" ",'Fill out report تعبئة التقرير'!Q39,"") | AO13: =IF('Fill out report تعبئة التقرير'!R39 > 0,'Fill out report تعبئة التقرير'!R39,"")
AH14: =IF('Fill out report تعبئة التقرير'!E40 >=" ",'Fill out report تعبئة التقرير'!E40,"") | AI14: =IF('Fill out report تعبئة التقرير'!I40 > 0,'Fill out report تعبئة التقرير'!I40,"") | AJ14: =IF('Fill out report تعبئة التقرير'!J40 > 0,'Fill out report تعبئة التقرير'!J40,"") | AK14: =IF('Fill out report تعبئة التقرير'!K40 >=0,'Fill out report تعبئة التقرير'!K40,"") -> 0 | AL14: =IF('Fill out report تعبئة التقرير'!L40 >=" ",'Fill out report تعبئة التقرير'!L40,"") | AM14: =IF('Fill out report تعبئة التقرير'!O40 > 0,'Fill out report تعبئة التقرير'!O40,"") | AN14: =IF('Fill out report تعبئة التقرير'!Q40 >=" ",'Fill out report تعبئة التقرير'!Q40,"") | AO14: =IF('Fill out report تعبئة التقرير'!R40 > 0,'Fill out report تعبئة التقرير'!R40,"")
... AH18: =IF('Fill out report تعبئة التقرير'!E44 >=" ",'Fill out report تعبئة التقرير'!E44,"") | AI18: =IF('Fill out report تعبئة التقرير'!I44 > 0,'Fill out report تعبئة التقرير'!I44,"") | AJ18: =IF('Fill out report تعبئة التقرير'!J44 > 0,'Fill out report تعبئة التقرير'!J44,"") | AK18: =IF('Fill out report تعبئة التقرير'!K44 >=0,'Fill out report تعبئة التقرير'!K44,"") -> 0 | AL18: =IF('Fill out report تعبئة التقرير'!L44 >=" ",'Fill out report تعبئة التقرير'!L44,"") | AM18: =IF('Fill out report تعبئة التقرير'!O44 > 0,'Fill out report تعبئة التقرير'!O44,"") | AN18: =IF('Fill out report تعبئة التقرير'!Q44 >=" ",'Fill out report تعبئة التقرير'!Q44,"") | AO18: =IF('Fill out report تعبئة التقرير'!R44 > 0,'Fill out report تعبئة التقرير'!R44,"")
AH19: =IF('Fill out report تعبئة التقرير'!E45 >=" ",'Fill out report تعبئة التقرير'!E45,"") | AI19: =IF('Fill out report تعبئة التقرير'!I45 > 0,'Fill out report تعبئة التقرير'!I45,"") | AJ19: =IF('Fill out report تعبئة التقرير'!J45 > 0,'Fill out report تعبئة التقرير'!J45,"") | AK19: =IF('Fill out report تعبئة التقرير'!K45 >=0,'Fill out report تعبئة التقرير'!K45,"") -> 0 | AL19: =IF('Fill out report تعبئة التقرير'!L45 >=" ",'Fill out report تعبئة التقرير'!L45,"") | AM19: =IF('Fill out report تعبئة التقرير'!O45 > 0,'Fill out report تعبئة التقرير'!O45,"") | AN19: =IF('Fill out report تعبئة التقرير'!Q45 >=" ",'Fill out report تعبئة التقرير'!Q45,"") | AO19: =IF('Fill out report تعبئة التقرير'!R76 > 0,'Fill out report تعبئة التقرير'!R76,"")
AH20: =IF('Fill out report تعبئة التقرير'!E46 >=" ",'Fill out report تعبئة التقرير'!E46,"") | AI20: =IF('Fill out report تعبئة التقرير'!I46 > 0,'Fill out report تعبئة التقرير'!I46,"") | AJ20: =IF('Fill out report تعبئة التقرير'!J46 > 0,'Fill out report تعبئة التقرير'!J46,"") | AK20: =IF('Fill out report تعبئة التقرير'!K46 >=0,'Fill out report تعبئة التقرير'!K46,"") -> 0 | AL20: =IF('Fill out report تعبئة التقرير'!L46 >=" ",'Fill out report تعبئة التقرير'!L46,"") | AM20: =IF('Fill out report تعبئة التقرير'!O46 > 0,'Fill out report تعبئة التقرير'!O46,"") | AN20: =IF('Fill out report تعبئة التقرير'!Q46 >=" ",'Fill out report تعبئة التقرير'!Q46,"") | AO20: =IF('Fill out report تعبئة التقرير'!R77 > 0,'Fill out report تعبئة التقرير'!R77,"")
AH21: =IF('Fill out report تعبئة التقرير'!E47 >=" ",'Fill out report تعبئة التقرير'!E47,"") | AI21: =IF('Fill out report تعبئة التقرير'!I47 > 0,'Fill out report تعبئة التقرير'!I47,"") | AJ21: =IF('Fill out report تعبئة التقرير'!J47 > 0,'Fill out report تعبئة التقرير'!J47,"") | AK21: =IF('Fill out report تعبئة التقرير'!K47 >=0,'Fill out report تعبئة التقرير'!K47,"") -> 0 | AL21: =IF('Fill out report تعبئة التقرير'!L47 >=" ",'Fill out report تعبئة التقرير'!L47,"") | AM21: =IF('Fill out report تعبئة التقرير'!O47 > 0,'Fill out report تعبئة التقرير'!O47,"") | AN21: =IF('Fill out report تعبئة التقرير'!Q47 >=" ",'Fill out report تعبئة التقرير'!Q47,"") | AO21: =IF('Fill out report تعبئة التقرير'!R78 > 0,'Fill out report تعبئة التقرير'!R78,"")
AH22: =IF('Fill out report تعبئة التقرير'!E48 >=" ",'Fill out report تعبئة التقرير'!E48,"") | AI22: =IF('Fill out report تعبئة التقرير'!I48 > 0,'Fill out report تعبئة التقرير'!I48,"") | AJ22: =IF('Fill out report تعبئة التقرير'!J48 > 0,'Fill out report تعبئة التقرير'!J48,"") | AK22: =IF('Fill out report تعبئة التقرير'!K48 >=0,'Fill out report تعبئة التقرير'!K48,"") -> 0 | AL22: =IF('Fill out report تعبئة التقرير'!L48 >=" ",'Fill out report تعبئة التقرير'!L48,"") | AM22: =IF('Fill out report تعبئة التقرير'!O48 > 0,'Fill out report تعبئة التقرير'!O48,"") | AN22: =IF('Fill out report تعبئة التقرير'!Q48 >=" ",'Fill out report تعبئة التقرير'!Q48,"") | AO22: =IF('Fill out report تعبئة التقرير'!R79 > 0,'Fill out report تعبئة التقرير'!R79,"")
AH23: =IF('Fill out report تعبئة التقرير'!E49 >=" ",'Fill out report تعبئة التقرير'!E49,"") | AI23: =IF('Fill out report تعبئة التقرير'!I49 > 0,'Fill out report تعبئة التقرير'!I49,"") | AJ23: =IF('Fill out report تعبئة التقرير'!J49 > 0,'Fill out report تعبئة التقرير'!J49,"") | AK23: =IF('Fill out report تعبئة التقرير'!K49 >=0,'Fill out report تعبئة التقرير'!K49,"") -> 0 | AL23: =IF('Fill out report تعبئة التقرير'!L49 >=" ",'Fill out report تعبئة التقرير'!L49,"") | AM23: =IF('Fill out report تعبئة التقرير'!O49 > 0,'Fill out report تعبئة التقرير'!O49,"") | AN23: =IF('Fill out report تعبئة التقرير'!Q49 >=" ",'Fill out report تعبئة التقرير'!Q49,"") | AO23: =IF('Fill out report تعبئة التقرير'!R80 > 0,'Fill out report تعبئة التقرير'!R80,"")
AH24: =IF('Fill out report تعبئة التقرير'!E50 >=" ",'Fill out report تعبئة التقرير'!E50,"") | AI24: =IF('Fill out report تعبئة التقرير'!I50 > 0,'Fill out report تعبئة التقرير'!I50,"") | AJ24: =IF('Fill out report تعبئة التقرير'!J50 > 0,'Fill out report تعبئة التقرير'!J50,"") | AK24: =IF('Fill out report تعبئة التقرير'!K50 >=0,'Fill out report تعبئة التقرير'!K50,"") -> 0 | AL24: =IF('Fill out report تعبئة التقرير'!L50 >=" ",'Fill out report تعبئة التقرير'!L50,"") | AM24: =IF('Fill out report تعبئة التقرير'!O50 > 0,'Fill out report تعبئة التقرير'!O50,"") | AN24: =IF('Fill out report تعبئة التقرير'!Q50 >=" ",'Fill out report تعبئة التقرير'!Q50,"") | AO24: =IF('Fill out report تعبئة التقرير'!R81 > 0,'Fill out report تعبئة التقرير'!R81,"")
AH25: =IF('Fill out report تعبئة التقرير'!E51 >=" ",'Fill out report تعبئة التقرير'!E51,"") | AI25: =IF('Fill out report تعبئة التقرير'!I51 > 0,'Fill out report تعبئة التقرير'!I51,"") | AJ25: =IF('Fill out report تعبئة التقرير'!J51 > 0,'Fill out report تعبئة التقرير'!J51,"") | AK25: =IF('Fill out report تعبئة التقرير'!K51 >=0,'Fill out report تعبئة التقرير'!K51,"") -> 0 | AL25: =IF('Fill out report تعبئة التقرير'!L51 >=" ",'Fill out report تعبئة التقرير'!L51,"") | AM25: =IF('Fill out report تعبئة التقرير'!O51 > 0,'Fill out report تعبئة التقرير'!O51,"") | AN25: =IF('Fill out report تعبئة التقرير'!Q51 >=" ",'Fill out report تعبئة التقرير'!Q51,"") | AO25: =IF('Fill out report تعبئة التقرير'!R82 > 0,'Fill out report تعبئة التقرير'!R82,"")
AH26: =IF('Fill out report تعبئة التقرير'!E52 >=" ",'Fill out report تعبئة التقرير'!E52,"") | AI26: =IF('Fill out report تعبئة التقرير'!I52 > 0,'Fill out report تعبئة التقرير'!I52,"") | AJ26: =IF('Fill out report تعبئة التقرير'!J52 > 0,'Fill out report تعبئة التقرير'!J52,"") | AK26: =IF('Fill out report تعبئة التقرير'!K52 >=0,'Fill out report تعبئة التقرير'!K52,"") -> 0 | AL26: =IF('Fill out report تعبئة التقرير'!L52 >=" ",'Fill out report تعبئة التقرير'!L52,"") | AM26: =IF('Fill out report تعبئة التقرير'!O52 > 0,'Fill out report تعبئة التقرير'!O52,"") | AN26: =IF('Fill out report تعبئة التقرير'!Q52 >=" ",'Fill out report تعبئة التقرير'!Q52,"") | AO26: =IF('Fill out report تعبئة التقرير'!R83 > 0,'Fill out report تعبئة التقرير'!R83,"")
AH27: =IF('Fill out report تعبئة التقرير'!E53 >=" ",'Fill out report تعبئة التقرير'!E53,"") | AI27: =IF('Fill out report تعبئة التقرير'!I53 > 0,'Fill out report تعبئة التقرير'!I53,"") | AJ27: =IF('Fill out report تعبئة التقرير'!J53 > 0,'Fill out report تعبئة التقرير'!J53,"") | AK27: =IF('Fill out report تعبئة التقرير'!K53 >=0,'Fill out report تعبئة التقرير'!K53,"") -> 0 | AL27: =IF('Fill out report تعبئة التقرير'!L53 >=" ",'Fill out report تعبئة التقرير'!L53,"") | AM27: =IF('Fill out report تعبئة التقرير'!O53 > 0,'Fill out report تعبئة التقرير'!O53,"") | AN27: =IF('Fill out report تعبئة التقرير'!Q53 >=" ",'Fill out report تعبئة التقرير'!Q53,"") | AO27: =IF('Fill out report تعبئة التقرير'!R84 > 0,'Fill out report تعبئة التقرير'!R84,"")
AH28: =IF('Fill out report تعبئة التقرير'!E54 >=" ",'Fill out report تعبئة التقرير'!E54,"") | AI28: =IF('Fill out report تعبئة التقرير'!I54 > 0,'Fill out report تعبئة التقرير'!I54,"") | AJ28: =IF('Fill out report تعبئة التقرير'!J54 > 0,'Fill out report تعبئة التقرير'!J54,"") | AK28: =IF('Fill out report تعبئة التقرير'!K54 >=0,'Fill out report تعبئة التقرير'!K54,"") -> 0 | AL28: =IF('Fill out report تعبئة التقرير'!L54 >=" ",'Fill out report تعبئة التقرير'!L54,"") | AM28: =IF('Fill out report تعبئة التقرير'!O54 > 0,'Fill out report تعبئة التقرير'!O54,"") | AN28: =IF('Fill out report تعبئة التقرير'!Q54 >=" ",'Fill out report تعبئة التقرير'!Q54,"") | AO28: =IF('Fill out report تعبئة التقرير'!R85 > 0,'Fill out report تعبئة التقرير'!R85,"")
AH29: =IF('Fill out report تعبئة التقرير'!E55 >=" ",'Fill out report تعبئة التقرير'!E55,"") | AI29: =IF('Fill out report تعبئة التقرير'!I55 > 0,'Fill out report تعبئة التقرير'!I55,"") | AJ29: =IF('Fill out report تعبئة التقرير'!J55 > 0,'Fill out report تعبئة التقرير'!J55,"") | AK29: =IF('Fill out report تعبئة التقرير'!K55 >=0,'Fill out report تعبئة التقرير'!K55,"") -> 0 | AL29: =IF('Fill out report تعبئة التقرير'!L55 >=" ",'Fill out report تعبئة التقرير'!L55,"") | AM29: =IF('Fill out report تعبئة التقرير'!O55 > 0,'Fill out report تعبئة التقرير'!O55,"") | AN29: =IF('Fill out report تعبئة التقرير'!Q55 >=" ",'Fill out report تعبئة التقرير'!Q55,"") | AO29: =IF('Fill out report تعبئة التقرير'!R86 > 0,'Fill out report تعبئة التقرير'!R86,"")
AH30: =IF('Fill out report تعبئة التقرير'!E56 >=" ",'Fill out report تعبئة التقرير'!E56,"") | AI30: =IF('Fill out report تعبئة التقرير'!I56 > 0,'Fill out report تعبئة التقرير'!I56,"") | AJ30: =IF('Fill out report تعبئة التقرير'!J56 > 0,'Fill out report تعبئة التقرير'!J56,"") | AK30: =IF('Fill out report تعبئة التقرير'!K56 >=0,'Fill out report تعبئة التقرير'!K56,"") -> 0 | AL30: =IF('Fill out report تعبئة التقرير'!L56 >=" ",'Fill out report تعبئة التقرير'!L56,"") | AM30: =IF('Fill out report تعبئة التقرير'!O56 > 0,'Fill out report تعبئة التقرير'!O56,"") | AN30: =IF('Fill out report تعبئة التقرير'!Q56 >=" ",'Fill out report تعبئة التقرير'!Q56,"") | AO30: =IF('Fill out report تعبئة التقرير'!R87 > 0,'Fill out report تعبئة التقرير'!R87,"")
... AH49: =IF('Fill out report تعبئة التقرير'!E75 >=" ",'Fill out report تعبئة التقرير'!E75,"") | AI49: =IF('Fill out report تعبئة التقرير'!I75 > 0,'Fill out report تعبئة التقرير'!I75,"") | AJ49: =IF('Fill out report تعبئة التقرير'!J75 > 0,'Fill out report تعبئة التقرير'!J75,"") | AK49: =IF('Fill out report تعبئة التقرير'!K75 >=0,'Fill out report تعبئة التقرير'!K75,"") -> 0 | AL49: =IF('Fill out report تعبئة التقرير'!L75 >=" ",'Fill out report تعبئة التقرير'!L75,"") | AM49: =IF('Fill out report تعبئة التقرير'!O75 > 0,'Fill out report تعبئة التقرير'!O75,"") | AN49: =IF('Fill out report تعبئة التقرير'!Q75 >=" ",'Fill out report تعبئة التقرير'!Q75,"") | AO49: =IF('Fill out report تعبئة التقرير'!R106 > 0,'Fill out report تعبئة التقرير'!R106,"")
AH50: =IF('Fill out report تعبئة التقرير'!E76 >=" ",'Fill out report تعبئة التقرير'!E76,"") | AI50: =IF('Fill out report تعبئة التقرير'!I76 > 0,'Fill out report تعبئة التقرير'!I76,"") | AJ50: =IF('Fill out report تعبئة التقرير'!J76 > 0,'Fill out report تعبئة التقرير'!J76,"") | AK50: =IF('Fill out report تعبئة التقرير'!K76 >=0,'Fill out report تعبئة التقرير'!K76,"") -> 0 | AL50: =IF('Fill out report تعبئة التقرير'!L76 >=" ",'Fill out report تعبئة التقرير'!L76,"") | AM50: =IF('Fill out report تعبئة التقرير'!O76 > 0,'Fill out report تعبئة التقرير'!O76,"") | AN50: =IF('Fill out report تعبئة التقرير'!Q76 >=" ",'Fill out report تعبئة التقرير'!Q76,"") | AO50: =IF('Fill out report تعبئة التقرير'!R106 > 0,'Fill out report تعبئة التقرير'!R106,"")

Sheet PMO Comments
A1: Date | B1: Time | C1: Name | D1: Comment

Sheet list
H2: Week
B3: Impact | C3: Score | H3: Week 1
B4: (Very High) عالي جداً | C4: 5 | H4: Week 2
B5: (High) عالي | C5: 4 | H5: Week 3
B6: (Medium) متوسط | C6: 3 | H6: Week 4
B7: (Low) منخفض | C7: 2 | H7: Week 5
B8: (Very Low) منخفض جداً | C8: 1 | H8: Week 6
H9: Week 7
A10: Rage In % | B10: Score | C10: Prob. Description | H10: Week 8
A11: > 75% | B11: 5 | C11: Very Likely | H11: Week 9
A12: 50% - 75% | B12: 4 | C12: Likely | H12: Week 10
A13: 20% - 50% | B13: 3 | C13: Possible | H13: Week 11
A14: 5% - 20% | B14: 2 | C14: Unlikely | H14: Week 12
A15: < 5% | B15: 1 | C15: Very Unlikely | H15: Week 13
H16: Week 14
H17: Week 15
B18: Issue | C18: Score | H18: Week 16
B19: (High) عالي | C19: 3 | H19: Week 17
B20: (Medium) متوسط | C20: 2 | H20: Week 18
B21: (Low) منخفض | C21: 1 | H21: Week 19
H22: Week 20
H23: Week 21
H24: Week 22
A25: Probability value | B25: Impact value | C25: Risks Severity | H25: Week 23
A26: =(IF('Fill out report تعبئة التقرير'!K104="> 75%",5, (IF('Fill out report تعبئة التقرير'!K104="50% - 75%",4, (IF('Fill out report تعبئة التقرير'!K104="20% - 50%",3, (IF('Fill out report تعبئة التقرير'!K104="5% - 20%",2, (IF('Fill out report تعبئة التقرير'!K104="< 5%",1,0)))))))))) -> 0 | B26: =(IF('Fill out report تعبئة التقرير'!L104="(Very High) عالي جداً",5, (IF('Fill out report تعبئة التقرير'!L104="(High) عالي",4, (IF('Fill out report تعبئة التقرير'!L104="(Medium) متوسط",3, (IF('Fill out report تعبئة التقرير'!L104="(Low) منخفض",2, (IF('Fill out report تعبئة التقرير'!L104="(Very Low) منخفض جداً",1,0)))))))))) -> 0 | C26: =A26*B26 -> 0 | H26: Week 24
A27: =(IF('Fill out report تعبئة التقرير'!K105="> 75%",5, (IF('Fill out report تعبئة التقرير'!K105="50% - 75%",4, (IF('Fill out report تعبئة التقرير'!K105="20% - 50%",3, (IF('Fill out report تعبئة التقرير'!K105="5% - 20%",2, (IF('Fill out report تعبئة التقرير'!K105="< 5%",1,0)))))))))) -> 0 | B27: =(IF('Fill out report تعبئة التقرير'!L105="(Very High) عالي جداً",5, (IF('Fill out report تعبئة التقرير'!L105="(High) عالي",4, (IF('Fill out report تعبئة التقرير'!L105="(Medium) متوسط",3, (IF('Fill out report تعبئة التقرير'!L105="(Low) منخفض",2, (IF('Fill out report تعبئة التقرير'!L105="(Very Low) منخفض جداً",1,0)))))))))) -> 0 | C27: =A27*B27 -> 0 | H27: Week 25
A28: =(IF('Fill out report تعبئة التقرير'!K106="> 75%",5, (IF('Fill out report تعبئة التقرير'!K106="50% - 75%",4, (IF('Fill out report تعبئة التقرير'!K106="20% - 50%",3, (IF('Fill out report تعبئة التقرير'!K106="5% - 20%",2, (IF('Fill out report تعبئة التقرير'!K106="< 5%",1,0)))))))))) -> 0 | B28: =(IF('Fill out report تعبئة التقرير'!L106="(Very High) عالي جداً",5, (IF('Fill out report تعبئة التقرير'!L106="(High) عالي",4, (IF('Fill out report تعبئة التقرير'!L106="(Medium) متوسط",3, (IF('Fill out report تعبئة التقرير'!L106="(Low) منخفض",2, (IF('Fill out report تعبئة التقرير'!L106="(Very Low) منخفض جداً",1,0)))))))))) -> 0 | C28: =A28*B28 -> 0 | H28: Week 26
A29: =(IF('Fill out report تعبئة التقرير'!K107="> 75%",5, (IF('Fill out report تعبئة التقرير'!K107="50% - 75%",4, (IF('Fill out report تعبئة التقرير'!K107="20% - 50%",3, (IF('Fill out report تعبئة التقرير'!K107="5% - 20%",2, (IF('Fill out report تعبئة التقرير'!K107="< 5%",1,0)))))))))) -> 0 | B29: =(IF('Fill out report تعبئة التقرير'!L107="(Very High) عالي جداً",5, (IF('Fill out report تعبئة التقرير'!L107="(High) عالي",4, (IF('Fill out report تعبئة التقرير'!L107="(Medium) متوسط",3, (IF('Fill out report تعبئة التقرير'!L107="(Low) منخفض",2, (IF('Fill out report تعبئة التقرير'!L107="(Very Low) منخفض جداً",1,0)))))))))) -> 0 | C29: =A29*B29 -> 0 | H29: Week 27
A30: =(IF('Fill out report تعبئة التقرير'!K108="> 75%",5, (IF('Fill out report تعبئة التقرير'!K108="50% - 75%",4, (IF('Fill out report تعبئة التقرير'!K108="20% - 50%",3, (IF('Fill out report تعبئة التقرير'!K108="5% - 20%",2, (IF('Fill out report تعبئة التقرير'!K108="< 5%",1,0)))))))))) -> 0 | B30: =(IF('Fill out report تعبئة التقرير'!L108="(Very High) عالي جداً",5, (IF('Fill out report تعبئة التقرير'!L108="(High) عالي",4, (IF('Fill out report تعبئة التقرير'!L108="(Medium) متوسط",3, (IF('Fill out report تعبئة التقرير'!L108="(Low) منخفض",2, (IF('Fill out report تعبئة التقرير'!L108="(Very Low) منخفض جداً",1,0)))))))))) -> 0 | C30: =A30*B30 -> 0 | H30: Week 28
A31: =(IF('Fill out report تعبئة التقرير'!K109="> 75%",5, (IF('Fill out report تعبئة التقرير'!K109="50% - 75%",4, (IF('Fill out report تعبئة التقرير'!K109="20% - 50%",3, (IF('Fill out report تعبئة التقرير'!K109="5% - 20%",2, (IF('Fill out report تعبئة التقرير'!K109="< 5%",1,0)))))))))) -> 0 | B31: =(IF('Fill out report تعبئة التقرير'!L109="(Very High) عالي جداً",5, (IF('Fill out report تعبئة التقرير'!L109="(High) عالي",4, (IF('Fill out report تعبئة التقرير'!L109="(Medium) متوسط",3, (IF('Fill out report تعبئة التقرير'!L109="(Low) منخفض",2, (IF('Fill out report تعبئة التقرير'!L109="(Very Low) منخفض جداً",1,0)))))))))) -> 0 | C31: =A31*B31 -> 0 | H31: Week 29
A32: =(IF('Fill out report تعبئة التقرير'!K110="> 75%",5, (IF('Fill out report تعبئة التقرير'!K110="50% - 75%",4, (IF('Fill out report تعبئة التقرير'!K110="20% - 50%",3, (IF('Fill out report تعبئة التقرير'!K110="5% - 20%",2, (IF('Fill out report تعبئة التقرير'!K110="< 5%",1,0)))))))))) -> 0 | B32: =(IF('Fill out report تعبئة التقرير'!L110="(Very High) عالي جداً",5, (IF('Fill out report تعبئة التقرير'!L110="(High) عالي",4, (IF('Fill out report تعبئة التقرير'!L110="(Medium) متوسط",3, (IF('Fill out report تعبئة التقرير'!L110="(Low) منخفض",2, (IF('Fill out report تعبئة التقرير'!L110="(Very Low) منخفض جداً",1,0)))))))))) -> 0 | C32: =A32*B32 -> 0 | H32: Week 30
A33: =(IF('Fill out report تعبئة التقرير'!K111="> 75%",5, (IF('Fill out report تعبئة التقرير'!K111="50% - 75%",4, (IF('Fill out report تعبئة التقرير'!K111="20% - 50%",3, (IF('Fill out report تعبئة التقرير'!K111="5% - 20%",2, (IF('Fill out report تعبئة التقرير'!K111="< 5%",1,0)))))))))) -> 0 | B33: =(IF('Fill out report تعبئة التقرير'!L111="(Very High) عالي جداً",5, (IF('Fill out report تعبئة التقرير'!L111="(High) عالي",4, (IF('Fill out report تعبئة التقرير'!L111="(Medium) متوسط",3, (IF('Fill out report تعبئة التقرير'!L111="(Low) منخفض",2, (IF('Fill out report تعبئة التقرير'!L111="(Very Low) منخفض جداً",1,0)))))))))) -> 0 | C33: =A33*B33 -> 0 | H33: Week 31
A34: =(IF('Fill out report تعبئة التقرير'!K112="> 75%",5, (IF('Fill out report تعبئة التقرير'!K112="50% - 75%",4, (IF('Fill out report تعبئة التقرير'!K112="20% - 50%",3, (IF('Fill out report تعبئة التقرير'!K112="5% - 20%",2, (IF('Fill out report تعبئة التقرير'!K112="< 5%",1,0)))))))))) -> 0 | B34: =(IF('Fill out report تعبئة التقرير'!L112="(Very High) عالي جداً",5, (IF('Fill out report تعبئة التقرير'!L112="(High) عالي",4, (IF('Fill out report تعبئة التقرير'!L112="(Medium) متوسط",3, (IF('Fill out report تعبئة التقرير'!L112="(Low) منخفض",2, (IF('Fill out report تعبئة التقرير'!L112="(Very Low) منخفض جداً",1,0)))))))))) -> 0 | C34: =A34*B34 -> 0 | H34: Week 32
A35: =(IF('Fill out report تعبئة التقرير'!K113="> 75%",5, (IF('Fill out report تعبئة التقرير'!K113="50% - 75%",4, (IF('Fill out report تعبئة التقرير'!K113="20% - 50%",3, (IF('Fill out report تعبئة التقرير'!K113="5% - 20%",2, (IF('Fill out report تعبئة التقرير'!K113="< 5%",1,0)))))))))) -> 0 | B35: =(IF('Fill out report تعبئة التقرير'!L113="(Very High) عالي جداً",5, (IF('Fill out report تعبئة التقرير'!L113="(High) عالي",4, (IF('Fill out report تعبئة التقرير'!L113="(Medium) متوسط",3, (IF('Fill out report تعبئة التقرير'!L113="(Low) منخفض",2, (IF('Fill out report تعبئة التقرير'!L113="(Very Low) منخفض جداً",1,0)))))))))) -> 0 | C35: =A35*B35 -> 0 | H35: Week 33
H36: Week 34
H37: Week 35
H38: Week 36
H39: Week 37
H40: Week 38
H41: Week 39
...

Sheet  مساعدة Help 
E6: PMO - Project Progress Report (PPR)
I10: ` | O10: How to use this PMO - Progress Report ?
E13: About this Template > | G13: Status reporting involves collecting and disseminating performance information to provide | L13: PMO
G14: stakeholders with information needed about the project. The report should include the following:
H15: * Accomplishments this reporting period.
H16: * Proposed activities for the next reporting period
H17: * Reference high severity risk identified in the Project Risks Log
H18: * Identify any predicted slippage to the Schedule , Quality and Scope along with cause and corrective actions
E20: Tips > | G20: * If you want to add more Risks , Issues and Milestone . Just click on "Headings" to show sheet headings and
G21: select the rows you want to unhide , Then right click and choose Unhide.
G22: * To print the Entire worksheet , use the keyboard and press " Ctrl + P " to open MS Excel 2010 print preview page.
E24: Legend > | G24: Please use this table to know what color to select in the traffic lights cells in (Overall Status Project) & (Risks):
G26: Schedule الجدول الزمني
I27: 1 | J27: متأخر [Unmanaged Delayed] | K27: if Schedule Delay > 10% of baseline schedule
I28: 2 | J28: احتمال وجود تأخير [ Managed Delayed] | K28: if Schedule Dela y< 10% of baseline schedule
I29: 3 | J29: وفق الخطة [On-Time]
G33: Risk Grade درجة الخطورة
I34: 1 | J34: (Low) منخفض
I35: 7 | J35: (Medium) متوسط
I36: 14 | J36: (High) عالي
G38: Risk Probability الإحتمالية الخطر
I39: Score | J39: Description | K39: Range in %
I40: 5 | J40: من المرجح جداً | K40: > 75%
I41: 4 | J41: من المرجح | K41: 0.75
I42: 3 | J42: من محتمل | K42: 20% - 50%
I43: 2 | J43: من غير المرجح | K43: 5% - 20%
I44: 1 | J44: من غير المرجح جداً | K44: < 5%
G46: Risk Scoring Matrix مصفوفة ترقيم الخطر
I47: (Probability x Impact ) Impact التأثير > | K47: (1) منخفض جداً Very Low | L47: (2) منخفض Low | M47: (3) متوسط Medium | N47: (4) عالي High | O47: (5) عالي جداً Very High
I48: Probability الإحتمالية> | J48: من غير المرجح جداً (1) | K48: 1 | L48: 2 | M48: 3 | N48: 4 | O48: 5
J49: من غير المرجح (2) | K49: 2 | L49: 4 | M49: 6 | N49: 8 | O49: 10
J50: من محتمل (3) | K50: 3 | L50: 6 | M50: 9 | N50: 12 | O50: 15
J51: من المرجح (4) | K51: 4 | L51: 8 | M51: 12 | N51: 16 | O51: 20
J52: من المرجح جداً (5) | K52: 5 | L52: 10 | M52: 15 | N52: 20 | O52: 25
G54: Milestones المعالم
I55: 1 | J55: Overdue تجاوز الحد
I56: 3 | J56: Not Due Yet / Completed On Time لم يبدأ /مكتمل حسب الوقت
D59: 1
E60: Please don't hesitate to contact ICT PMO if you need to increase the number of rows or to customize the template.
